Workbook

Sheet Read Me
A1: Villa Somalia SCADA – Project Bill of Material
A2: Project | B2: Solarization Villa Somalia – Power Plant Control & SCADA System
A3: Client | B3: Ministry of Energy & Water Resources – Somalia
A4: Contractor | B4: Blueflag Energy Co. Ltd
A5: Platform | B5: Schneider Electric: Modicon M580 + X80, Modicon Edge I/O NTS, Easergy P5M30, PowerLogic PM5320, PAS600, EcoStruxure Machine SCADA Expert
A6: Basis | B6: Drawings BFE/PR/26/01-SCADA-001 (architecture) and -002 (communication network), I/O list docs/villa-somalia-io-list.csv, Schneider offer 'Villa Somalia' v1 and its BOM workbook.
A7: Revision | B7: Rev A – draft for internal review, 22-OCT-2026
A9: How to read
A10: BOM by Location | B10: Every line by panel / location, with source, status and remarks. Subtotals per location.
A11: BOM by Reference | B11: Same items summed per part number, with offer quantity and difference.
A12: Summary | B12: Priced subtotal and open RFQ lines per location.
A13: Changes vs Offer | B13: Every quantity change, replacement, removal and addition against the Schneider offer, plus options needing a decision.
A14: IO Capacity | B14: Hard-wired DI/DO required by the I/O list against channels installed, with the spare margin as an input.
A16: Cell colours
A17: Blue text | B17: Input: quantity, unit price or count you can change.
A18: Yellow fill | B18: Unit price not available yet – request a quotation (RFQ).
A19: Green text | B19: Value linked from another sheet.
A21: Status values
A22: Offered | B22: In the Schneider offer (quantity may be corrected).
A23: Added | B23: Needed by the drawings or panel design; part number is a catalogue reference.
A24: Added – ref. TBC | B24: Needed; exact part number to be selected / confirmed with the supplier.
A25: By others | B25: Supplied by another package vendor; listed so the interface is not missed. Price 0.
A27: Key open points
A28: Prices | B28: Unit prices are copied from the offer workbook. P5M30 and PM5320 had no price there. Currency to be confirmed.
A29: Field switches | B29: Five field switches and SW2 need 2 single-mode fibre ports; MCSESM083F23F1 is copper only. Select the fibre variant with Schneider.
A30: Second CPU | B30: The offer's second BMEP582040 is a spare. It is not a hot-standby pair (see option O2).
A31: PVSCL60E | B31: Removed: the site uses Sungrow SG350HX supplied by the PV EPC.
A32: Cable lengths | B32: Fibre, Ethernet and RS485 lengths are estimates; confirm from the cable route drawings.

Sheet BOM by Location
A1: Villa Somalia SCADA – Bill of Material by Location (Schneider Electric architecture, drawings BFE/PR/26/01-SCADA-001/002)
A2: Blue = input quantity / price. Yellow = price to be obtained (RFQ). Prices in offer currency (to be confirmed).
A4: Item | B4: Loc | C4: Location | D4: Device / tag | E4: Reference | F4: Description | G4: Qty | H4: Unit | I4: Unit price | J4: Total price | K4: Source | L4: Status | M4: Remarks
B5: A | C5: Control room – SCADA, servers and network (Level 2/3)
A6: 10 | B6: A | C6: Control room – SCADA, servers and network (Level 2/3) | D6: HMI-01/02 | E6: HMIP67GD0F88BE7N00 | F6: Harmony P6 industrial PC – operator stations (configuration per offer) | G6: 2 | H6: pc | I6: 6750 | J6: =IF(ISNUMBER(I6),G6*I6,"") -> 13500 | K6: Offer | L6: Offered | M6: Offer gives no description; confirm screen size, CPU and OS.
A7: 20 | B7: A | C7: Control room – SCADA, servers and network (Level 2/3) | D7: HMI-01/02 | E7: HMIEMSE3PRT4KA | F7: EcoStruxure Machine SCADA Expert 3rd-party runtime 4K tags, digital licence | G7: 2 | H7: pc | I7: 4699.914 | J7: =IF(ISNUMBER(I7),G7*I7,"") -> 9399.8279 | K7: Offer | L7: Offered | M7: 4K tags per station; I/O list holds 958 signals plus internal tags.
A8: 30 | B8: A | C8: Control room – SCADA, servers and network (Level 2/3) | D8: ENG-01 | E8: HMIEMSEBT4KA | F8: EcoStruxure Machine SCADA Expert build-time 4K tags, digital licence | G8: 1 | H8: pc | I8: 2749.0325 | J8: =IF(ISNUMBER(I8),G8*I8,"") -> 2749.0325 | K8: Offer | L8: Offered
A9: 40 | B9: A | C9: Control room – SCADA, servers and network (Level 2/3) | D9: SRV-01 | E9: TBC-SRV-01 | F9: SCADA server / historian, rack industrial server, RAID 1, redundant PSU, 13-month storage | G9: 1 | H9: pc | J9: =IF(ISNUMBER(I9),G9*I9,"") | K9: Sheet 001 | L9: Added – ref. TBC | M9: Not in offer. Needed for historian and alarm/event archive.
A10: 50 | B10: A | C10: Control room – SCADA, servers and network (Level 2/3) | D10: ENG-01 | E10: TBC-ENG-01 | F10: Engineering workstation (laptop) with EcoStruxure Control Expert licence for M580 | G10: 1 | H10: pc | J10: =IF(ISNUMBER(I10),G10*I10,"") | K10: Sheet 001 | L10: Added – ref. TBC | M10: Not in offer. Needed to program and maintain the M580.
A11: 60 | B11: A | C11: Control room – SCADA, servers and network (Level 2/3) | D11: GPS-01 | E11: TBC-GPS-01 | F11: GPS master clock with antenna, NTP / PTP server | G11: 1 | H11: pc | J11: =IF(ISNUMBER(I11),G11*I11,"") | K11: Sheet 001 | L11: Added – ref. TBC | M11: Time source for 1 ms relay event stamping.
A12: 70 | B12: A | C12: Control room – SCADA, servers and network (Level 2/3) | D12: FW-01 | E12: TBC-FW-01 | F12: Industrial firewall, DMZ between Level 2 and Level 3 | G12: 1 | H12: pc | J12: =IF(ISNUMBER(I12),G12*I12,"") | K12: Sheet 001 | L12: Added – ref. TBC | M12: Only conduit to remote access (client policy TBC).
A13: 80 | B13: A | C13: Control room – SCADA, servers and network (Level 2/3) | D13: SW1 | E13: MCSESM083F23F1 | F13: Modicon Extended Managed Switch 8TX – SCADA LAN (SW1) | G13: 1 | H13: pc | I13: 1609.695 | J13: =IF(ISNUMBER(I13),G13*I13,"") -> 1609.695 | K13: Offer | L13: Offered | M13: Offer has 2; the second is replaced by an FO variant for SW2.
A14: 90 | B14: A | C14: Control room – SCADA, servers and network (Level 2/3) | D14: UPS-01 | E14: SRT6KRMXLI | F14: APC Smart-UPS SRT 6 kVA rack/tower, 230 V – SCADA, PLC and switches | G14: 1 | H14: pc | J14: =IF(ISNUMBER(I14),G14*I14,"") | K14: Sheet 001 | L14: Added | M14: Size from load list; add battery packs if > 30 min autonomy is required.
A15: 100 | B15: A | C15: Control room – SCADA, servers and network (Level 2/3) | D15: UPS-01 | E15: AP9641 | F15: UPS Network Management Card 3 (SNMP / Modbus TCP) | G15: 1 | H15: pc | J15: =IF(ISNUMBER(I15),G15*I15,"") | K15: Sheet 002 | L15: Added | M15: Address 10.10.30.61.
A16: 110 | B16: A | C16: Control room – SCADA, servers and network (Level 2/3) | D16: RACK-CR | E16: AR3100 | F16: NetShelter SX 42U 600 × 1070 mm rack – server, SW1, FW-01, GPS-01, UPS-01 | G16: 1 | H16: pc | J16: =IF(ISNUMBER(I16),G16*I16,"") | K16: Sheet 001 | L16: Added
A17: 120 | B17: A | C17: Control room – SCADA, servers and network (Level 2/3) | D17: CONSOLE | E17: TBC-CONSOLE | F17: Operator console, 2 positions, 2 × 27" monitors each, keyboard / mouse | G17: 1 | H17: lot | J17: =IF(ISNUMBER(I17),G17*I17,"") | K17: Sheet 001 | L17: Added – ref. TBC | M17: May be by building contractor.
F18: Subtotal A – Control room – SCADA, servers and network (Level 2/3) | J18: =SUBTOTAL(9,J6:J17) -> 27258.555 | L18: =COUNTIFS(B6:B17,"A",I6:I17,"")&" lines RFQ" -> 8 lines RFQ
B20: B | C20: Main PLC panel – Drop 0 (control room)
A21: 130 | B21: B | C21: Main PLC panel – Drop 0 (control room) | D21: PLC-MAIN | E21: BMEXBP0800 | F21: PLC 8-slot Ethernet backplane | G21: 1 | H21: pc | I21: 227.682 | J21: =IF(ISNUMBER(I21),G21*I21,"") -> 227.682 | K21: Offer | L21: Offered
A22: 140 | B22: B | C22: Main PLC panel – Drop 0 (control room) | D22: PLC-MAIN | E22: BMXCPS3020 | F22: X80 DC power supply 24–48 V DC, 32 W, isolated | G22: 1 | H22: pc | I22: 320.0265 | J22: =IF(ISNUMBER(I22),G22*I22,"") -> 320.0265 | K22: Offer | L22: Offered
A23: 150 | B23: B | C23: Main PLC panel – Drop 0 (control room) | D23: PLC-MAIN | E23: BMEP582040 | F23: M580 CPU level 2, remote and distributed I/O – plant controller (PPC) | G23: 1 | H23: pc | I23: 2337.7635 | J23: =IF(ISNUMBER(I23),G23*I23,"") -> 2337.7635 | K23: Offer | L23: Offered | M23: Second offer CPU is the spare (location S).
A24: 160 | B24: B | C24: Main PLC panel – Drop 0 (control room) | D24: PLC-MAIN | E24: BMENOC0311 | F24: M580 I/O scanner module, FactoryCast, EtherNet/IP & Modbus TCP, 3 ports | G24: 2 | H24: pc | I24: 887.94 | J24: =IF(ISNUMBER(I24),G24*I24,"") -> 1775.88 | K24: Sheet 001 | L24: Offered | M24: #1 SCADA LAN, #2 second SCADA LAN path. Offer has 1 in use (+1).
A25: 170 | B25: B | C25: Main PLC panel – Drop 0 (control room) | D25: PLC-MAIN | E25: BMENOC0321 | F25: M580 I/O scanner module, IP forwarding, coated – device network | G25: 1 | H25: pc | I25: 1014.795 | J25: =IF(ISNUMBER(I25),G25*I25,"") -> 1014.795 | K25: Offer | L25: Offered
A26: 180 | B26: B | C26: Main PLC panel – Drop 0 (control room) | D26: PLC-MAIN | E26: BMXDDI3202K | F26: X80 digital input module 32 ch 24 V DC sink | G26: 1 | H26: pc | I26: 212.1705 | J26: =IF(ISNUMBER(I26),G26*I26,"") -> 212.1705 | K26: Offer | L26: Offered
A27: 190 | B27: B | C27: Main PLC panel – Drop 0 (control room) | D27: PLC-MAIN | E27: BMXDDO3202K | F27: X80 digital output module 32 ch 24 V DC source | G27: 1 | H27: pc | I27: 250.218 | J27: =IF(ISNUMBER(I27),G27*I27,"") -> 250.218 | K27: Offer | L27: Offered
A28: 200 | B28: B | C28: Main PLC panel – Drop 0 (control room) | D28: PLC-MAIN | E28: BMXFCW303 | F28: 3 m pre-equipped cable, 1 connector + free wires (one per 32-ch module) | G28: 2 | H28: pc | I28: 51.5835 | J28: =IF(ISNUMBER(I28),G28*I28,"") -> 103.167 | K28: Offer | L28: Offered
A29: 210 | B29: B | C29: Main PLC panel – Drop 0 (control room) | D29: PLC-MAIN | E29: ABL8RPS24100 | F29: Phaseo power supply 24 V DC 10 A | G29: 2 | H29: pc | J29: =IF(ISNUMBER(I29),G29*I29,"") | K29: Panel design | L29: Added | M29: Redundant 24 V DC for PLC and I/O.
A30: 220 | B30: B | C30: Main PLC panel – Drop 0 (control room) | D30: PLC-MAIN | E30: ABL8RED24400 | F30: Phaseo redundancy module 24 V DC 40 A | G30: 1 | H30: pc | J30: =IF(ISNUMBER(I30),G30*I30,"") | K30: Panel design | L30: Added
A31: 230 | B31: B | C31: Main PLC panel – Drop 0 (control room) | D31: PLC-MAIN | E31: RSB1A120BD | F31: Zelio RSB interposing relay 1 C/O 12 A, 24 V DC coil | G31: 8 | H31: pc | J31: =IF(ISNUMBER(I31),G31*I31,"") | K31: Panel design | L31: Added | M31: DO isolation to field circuits.
A32: 240 | B32: B | C32: Main PLC panel – Drop 0 (control room) | D32: PLC-MAIN | E32: RSZE1S35M | F32: Socket for RSB1A relay, with clip | G32: 8 | H32: pc | J32: =IF(ISNUMBER(I32),G32*I32,"") | K32: Panel design | L32: Added
A33: 250 | B33: B | C33: Main PLC panel – Drop 0 (control room) | D33: PLC-MAIN | E33: NSYTRV42 | F33: Linergy TR screw terminal block 4 mm², feed-through | G33: 150 | H33: pc | J33: =IF(ISNUMBER(I33),G33*I33,"") | K33: Panel design | L33: Added | M33: Estimate; confirm from wiring diagrams.
A34: 260 | B34: B | C34: Main PLC panel – Drop 0 (control room) | D34: PLC-MAIN | E34: TBC-ENC-PLC | F34: Floor-standing enclosure 2000 × 800 × 600 IP55, fan, light, socket, earthing | G34: 1 | H34: pc | J34: =IF(ISNUMBER(I34),G34*I34,"") | K34: Panel design | L34: Added – ref. TBC | M34: Spacial SM or equivalent.
F35: Subtotal B – Main PLC panel – Drop 0 (control room) | J35: =SUBTOTAL(9,J21:J34) -> 6241.7025 | L35: =COUNTIFS(B21:B34,"B",I21:I34,"")&" lines RFQ" -> 6 lines RFQ
B37: C | C37: Rack 2 panel – Drop 1, MV / BESS / DG I/O and device network (11 kV GIS room)
A38: 270 | B38: C | C38: Rack 2 panel – Drop 1, MV / BESS / DG I/O and device network (11 kV GIS room) | D38: PLC-R2 | E38: BMEXBP1200 | F38: PLC 12-slot Ethernet backplane | G38: 1 | H38: pc | I38: 322.7805 | J38: =IF(ISNUMBER(I38),G38*I38,"") -> 322.7805 | K38: Offer | L38: Offered
A39: 280 | B39: C | C39: Rack 2 panel – Drop 1, MV / BESS / DG I/O and device network (11 kV GIS room) | D39: PLC-R2 | E39: BMXCPS3020 | F39: X80 DC power supply 24–48 V DC, 32 W, isolated | G39: 1 | H39: pc | I39: 320.0265 | J39: =IF(ISNUMBER(I39),G39*I39,"") -> 320.0265 | K39: Offer | L39: Offered
A40: 290 | B40: C | C40: Rack 2 panel – Drop 1, MV / BESS / DG I/O and device network (11 kV GIS room) | D40: PLC-R2 | E40: BMECRA31210 | F40: X80 performance Ethernet drop adapter | G40: 1 | H40: pc | I40: 789.4575 | J40: =IF(ISNUMBER(I40),G40*I40,"") -> 789.4575 | K40: Offer | L40: Offered
A41: 300 | B41: C | C41: Rack 2 panel – Drop 1, MV / BESS / DG I/O and device network (11 kV GIS room) | D41: PLC-R2 | E41: BMXDDI3202K | F41: X80 digital input module 32 ch 24 V DC sink | G41: 5 | H41: pc | I41: 212.1705 | J41: =IF(ISNUMBER(I41),G41*I41,"") -> 1060.8525 | K41: I/O list | L41: Offered | M41: Offer 3; +2 for 138 hard-wired DI + 20 % spare (see IO Capacity).
A42: 310 | B42: C | C42: Rack 2 panel – Drop 1, MV / BESS / DG I/O and device network (11 kV GIS room) | D42: PLC-R2 | E42: BMXDDO3202K | F42: X80 digital output module 32 ch 24 V DC source | G42: 2 | H42: pc | I42: 250.218 | J42: =IF(ISNUMBER(I42),G42*I42,"") -> 500.436 | K42: Offer | L42: Offered
A43: 320 | B43: C | C43: Rack 2 panel – Drop 1, MV / BESS / DG I/O and device network (11 kV GIS room) | D43: PLC-R2 | E43: BMXFCW303 | F43: 3 m pre-equipped cable, 1 connector + free wires (one per 32-ch module) | G43: 7 | H43: pc | I43: 51.5835 | J43: =IF(ISNUMBER(I43),G43*I43,"") -> 361.0845 | K43: I/O list | L43: Offered | M43: One per module (5 DI + 2 DO).
...

Sheet BOM by Reference
A1: Bill of Material by Reference (quantities summed from 'BOM by Location')
A3: Reference | B3: Description | C3: Total qty | D3: Unit | E3: Unit price | F3: Total price | G3: Status | H3: Offer qty | I3: Change
A4: HMIP67GD0F88BE7N00 | B4: Harmony P6 industrial PC – operator stations (configuration per offer) | C4: =SUMIF('BOM by Location'!$E$5:$E$170,A4,'BOM by Location'!$G$5:$G$170) -> 2 | D4: pc | E4: =IFERROR(IF(INDEX('BOM by Location'!$I$5:$I$170,MATCH(A4,'BOM by Location'!$E$5:$E$170,0))="","",INDEX('BOM by Location'!$I$5:$I$170,MATCH(A4,'BOM by Location'!$E$5:$E$170,0))),"") -> 6750 | F4: =IF(ISNUMBER(E4),IF(E4="","",C4*E4),"") -> 13500 | G4: Offered | H4: 2 | I4: =C4-H4 -> 0
A5: HMIEMSE3PRT4KA | B5: EcoStruxure Machine SCADA Expert 3rd-party runtime 4K tags, digital licence | C5: =SUMIF('BOM by Location'!$E$5:$E$170,A5,'BOM by Location'!$G$5:$G$170) -> 2 | D5: pc | E5: =IFERROR(IF(INDEX('BOM by Location'!$I$5:$I$170,MATCH(A5,'BOM by Location'!$E$5:$E$170,0))="","",INDEX('BOM by Location'!$I$5:$I$170,MATCH(A5,'BOM by Location'!$E$5:$E$170,0))),"") -> 4699.914 | F5: =IF(ISNUMBER(E5),IF(E5="","",C5*E5),"") -> 9399.8279 | G5: Offered | H5: 2 | I5: =C5-H5 -> 0
A6: HMIEMSEBT4KA | B6: EcoStruxure Machine SCADA Expert build-time 4K tags, digital licence | C6: =SUMIF('BOM by Location'!$E$5:$E$170,A6,'BOM by Location'!$G$5:$G$170) -> 1 | D6: pc | E6: =IFERROR(IF(INDEX('BOM by Location'!$I$5:$I$170,MATCH(A6,'BOM by Location'!$E$5:$E$170,0))="","",INDEX('BOM by Location'!$I$5:$I$170,MATCH(A6,'BOM by Location'!$E$5:$E$170,0))),"") -> 2749.0325 | F6: =IF(ISNUMBER(E6),IF(E6="","",C6*E6),"") -> 2749.0325 | G6: Offered | H6: 1 | I6: =C6-H6 -> 0
A7: TBC-SRV-01 | B7: SCADA server / historian, rack industrial server, RAID 1, redundant PSU, 13-month storage | C7: =SUMIF('BOM by Location'!$E$5:$E$170,A7,'BOM by Location'!$G$5:$G$170) -> 1 | D7: pc | E7: =IFERROR(IF(INDEX('BOM by Location'!$I$5:$I$170,MATCH(A7,'BOM by Location'!$E$5:$E$170,0))="","",INDEX('BOM by Location'!$I$5:$I$170,MATCH(A7,'BOM by Location'!$E$5:$E$170,0))),"") | F7: =IF(ISNUMBER(E7),IF(E7="","",C7*E7),"") | G7: Added – ref. TBC | H7: 0 | I7: =C7-H7 -> 1
A8: TBC-ENG-01 | B8: Engineering workstation (laptop) with EcoStruxure Control Expert licence for M580 | C8: =SUMIF('BOM by Location'!$E$5:$E$170,A8,'BOM by Location'!$G$5:$G$170) -> 1 | D8: pc | E8: =IFERROR(IF(INDEX('BOM by Location'!$I$5:$I$170,MATCH(A8,'BOM by Location'!$E$5:$E$170,0))="","",INDEX('BOM by Location'!$I$5:$I$170,MATCH(A8,'BOM by Location'!$E$5:$E$170,0))),"") | F8: =IF(ISNUMBER(E8),IF(E8="","",C8*E8),"") | G8: Added – ref. TBC | H8: 0 | I8: =C8-H8 -> 1
A9: TBC-GPS-01 | B9: GPS master clock with antenna, NTP / PTP server | C9: =SUMIF('BOM by Location'!$E$5:$E$170,A9,'BOM by Location'!$G$5:$G$170) -> 1 | D9: pc | E9: =IFERROR(IF(INDEX('BOM by Location'!$I$5:$I$170,MATCH(A9,'BOM by Location'!$E$5:$E$170,0))="","",INDEX('BOM by Location'!$I$5:$I$170,MATCH(A9,'BOM by Location'!$E$5:$E$170,0))),"") | F9: =IF(ISNUMBER(E9),IF(E9="","",C9*E9),"") | G9: Added – ref. TBC | H9: 0 | I9: =C9-H9 -> 1
A10: TBC-FW-01 | B10: Industrial firewall, DMZ between Level 2 and Level 3 | C10: =SUMIF('BOM by Location'!$E$5:$E$170,A10,'BOM by Location'!$G$5:$G$170) -> 1 | D10: pc | E10: =IFERROR(IF(INDEX('BOM by Location'!$I$5:$I$170,MATCH(A10,'BOM by Location'!$E$5:$E$170,0))="","",INDEX('BOM by Location'!$I$5:$I$170,MATCH(A10,'BOM by Location'!$E$5:$E$170,0))),"") | F10: =IF(ISNUMBER(E10),IF(E10="","",C10*E10),"") | G10: Added – ref. TBC | H10: 0 | I10: =C10-H10 -> 1
A11: MCSESM083F23F1 | B11: Modicon Extended Managed Switch 8TX – SCADA LAN (SW1) | C11: =SUMIF('BOM by Location'!$E$5:$E$170,A11,'BOM by Location'!$G$5:$G$170) -> 1 | D11: pc | E11: =IFERROR(IF(INDEX('BOM by Location'!$I$5:$I$170,MATCH(A11,'BOM by Location'!$E$5:$E$170,0))="","",INDEX('BOM by Location'!$I$5:$I$170,MATCH(A11,'BOM by Location'!$E$5:$E$170,0))),"") -> 1609.695 | F11: =IF(ISNUMBER(E11),IF(E11="","",C11*E11),"") -> 1609.695 | G11: Offered | H11: 2 | I11: =C11-H11 -> -1
A12: SRT6KRMXLI | B12: APC Smart-UPS SRT 6 kVA rack/tower, 230 V – SCADA, PLC and switches | C12: =SUMIF('BOM by Location'!$E$5:$E$170,A12,'BOM by Location'!$G$5:$G$170) -> 1 | D12: pc | E12: =IFERROR(IF(INDEX('BOM by Location'!$I$5:$I$170,MATCH(A12,'BOM by Location'!$E$5:$E$170,0))="","",INDEX('BOM by Location'!$I$5:$I$170,MATCH(A12,'BOM by Location'!$E$5:$E$170,0))),"") | F12: =IF(ISNUMBER(E12),IF(E12="","",C12*E12),"") | G12: Added | H12: 0 | I12: =C12-H12 -> 1
A13: AP9641 | B13: UPS Network Management Card 3 (SNMP / Modbus TCP) | C13: =SUMIF('BOM by Location'!$E$5:$E$170,A13,'BOM by Location'!$G$5:$G$170) -> 1 | D13: pc | E13: =IFERROR(IF(INDEX('BOM by Location'!$I$5:$I$170,MATCH(A13,'BOM by Location'!$E$5:$E$170,0))="","",INDEX('BOM by Location'!$I$5:$I$170,MATCH(A13,'BOM by Location'!$E$5:$E$170,0))),"") | F13: =IF(ISNUMBER(E13),IF(E13="","",C13*E13),"") | G13: Added | H13: 0 | I13: =C13-H13 -> 1
A14: AR3100 | B14: NetShelter SX 42U 600 × 1070 mm rack – server, SW1, FW-01, GPS-01, UPS-01 | C14: =SUMIF('BOM by Location'!$E$5:$E$170,A14,'BOM by Location'!$G$5:$G$170) -> 1 | D14: pc | E14: =IFERROR(IF(INDEX('BOM by Location'!$I$5:$I$170,MATCH(A14,'BOM by Location'!$E$5:$E$170,0))="","",INDEX('BOM by Location'!$I$5:$I$170,MATCH(A14,'BOM by Location'!$E$5:$E$170,0))),"") | F14: =IF(ISNUMBER(E14),IF(E14="","",C14*E14),"") | G14: Added | H14: 0 | I14: =C14-H14 -> 1
A15: TBC-CONSOLE | B15: Operator console, 2 positions, 2 × 27" monitors each, keyboard / mouse | C15: =SUMIF('BOM by Location'!$E$5:$E$170,A15,'BOM by Location'!$G$5:$G$170) -> 1 | D15: lot | E15: =IFERROR(IF(INDEX('BOM by Location'!$I$5:$I$170,MATCH(A15,'BOM by Location'!$E$5:$E$170,0))="","",INDEX('BOM by Location'!$I$5:$I$170,MATCH(A15,'BOM by Location'!$E$5:$E$170,0))),"") | F15: =IF(ISNUMBER(E15),IF(E15="","",C15*E15),"") | G15: Added – ref. TBC | H15: 0 | I15: =C15-H15 -> 1
... A65: TBC-SVC-FO | B65: Fibre installation, splicing and OTDR testing | C65: =SUMIF('BOM by Location'!$E$5:$E$170,A65,'BOM by Location'!$G$5:$G$170) -> 1 | D65: lot | E65: =IFERROR(IF(INDEX('BOM by Location'!$I$5:$I$170,MATCH(A65,'BOM by Location'!$E$5:$E$170,0))="","",INDEX('BOM by Location'!$I$5:$I$170,MATCH(A65,'BOM by Location'!$E$5:$E$170,0))),"") | F65: =IF(ISNUMBER(E65),IF(E65="","",C65*E65),"") | G65: Added – ref. TBC | H65: 0 | I65: =C65-H65 -> 1
B66: TOTAL – priced lines | F66: =SUM(F4:F65) -> 104639.19
B67: Check: equals 'BOM by Location' total | F67: =IF(ABS(F66-'BOM by Location'!J172)<0.01,"OK","MISMATCH") -> OK

Sheet Summary
A1: Cost summary by location
A3: Loc | B3: Location | C3: Priced subtotal | D3: Lines RFQ | E3: Share of priced total
A4: A | B4: Control room – SCADA, servers and network (Level 2/3) | C4: ='BOM by Location'!J18 -> 27258.555 | D4: =COUNTIFS('BOM by Location'!$B$5:$B$170,A4,'BOM by Location'!$I$5:$I$170,"",'BOM by Location'!$E$5:$E$170,"<>") -> 8 | E4: =IF($C$17=0,0,C4/$C$17) -> 0.26050045
A5: B | B5: Main PLC panel – Drop 0 (control room) | C5: ='BOM by Location'!J35 -> 6241.7025 | D5: =COUNTIFS('BOM by Location'!$B$5:$B$170,A5,'BOM by Location'!$I$5:$I$170,"",'BOM by Location'!$E$5:$E$170,"<>") -> 6 | E5: =IF($C$17=0,0,C5/$C$17) -> 0.059649761
A6: C | B6: Rack 2 panel – Drop 1, MV / BESS / DG I/O and device network (11 kV GIS room) | C6: ='BOM by Location'!J53 -> 3777.48 | D6: =COUNTIFS('BOM by Location'!$B$5:$B$170,A6,'BOM by Location'!$I$5:$I$170,"",'BOM by Location'!$E$5:$E$170,"<>") -> 7 | E6: =IF($C$17=0,0,C6/$C$17) -> 0.036100051
A7: D | B7: 11 kV GIS combiner panel – protection relays | C7: ='BOM by Location'!J57 -> 0 | D7: =COUNTIFS('BOM by Location'!$B$5:$B$170,A7,'BOM by Location'!$I$5:$I$170,"",'BOM by Location'!$E$5:$E$170,"<>") -> 1 | E7: =IF($C$17=0,0,C7/$C$17) -> 0
A8: E1 | B8: President office TX station – LVDB 1 (NTS-LVP1/LVP2) | C8: ='BOM by Location'!J78 -> 6168.6236 | D8: =COUNTIFS('BOM by Location'!$B$5:$B$170,A8,'BOM by Location'!$I$5:$I$170,"",'BOM by Location'!$E$5:$E$170,"<>") -> 6 | E8: =IF($C$17=0,0,C8/$C$17) -> 0.058951372
A9: E2 | B9: Prime Minister office TX station – LVDB 2 (NTS-LVM1) | C9: ='BOM by Location'!J99 -> 3459.6002 | D9: =COUNTIFS('BOM by Location'!$B$5:$B$170,A9,'BOM by Location'!$I$5:$I$170,"",'BOM by Location'!$E$5:$E$170,"<>") -> 6 | E9: =IF($C$17=0,0,C9/$C$17) -> 0.033062186
A10: F | B10: PV inverter station – PV areas 1–4 (NTS-PV1…PV4) | C10: ='BOM by Location'!J118 -> 13838.401 | D10: =COUNTIFS('BOM by Location'!$B$5:$B$170,A10,'BOM by Location'!$I$5:$I$170,"",'BOM by Location'!$E$5:$E$170,"<>") -> 4 | E10: =IF($C$17=0,0,C10/$C$17) -> 0.13224874
A11: G | B11: BESS container interface | C11: ='BOM by Location'!J123 -> 0 | D11: =COUNTIFS('BOM by Location'!$B$5:$B$170,A11,'BOM by Location'!$I$5:$I$170,"",'BOM by Location'!$E$5:$E$170,"<>") -> 2 | E11: =IF($C$17=0,0,C11/$C$17) -> 0
A12: H | B12: Diesel generator area | C12: ='BOM by Location'!J128 -> 0 | D12: =COUNTIFS('BOM by Location'!$B$5:$B$170,A12,'BOM by Location'!$I$5:$I$170,"",'BOM by Location'!$E$5:$E$170,"<>") -> 2 | E12: =IF($C$17=0,0,C12/$C$17) -> 0
A13: J | B13: Communication cabling and infrastructure | C13: ='BOM by Location'!J138 -> 0 | D13: =COUNTIFS('BOM by Location'!$B$5:$B$170,A13,'BOM by Location'!$I$5:$I$170,"",'BOM by Location'!$E$5:$E$170,"<>") -> 7 | E13: =IF($C$17=0,0,C13/$C$17) -> 0
A14: K | B14: Third-party interfaces (by others – listed for completeness) | C14: ='BOM by Location'!J147 -> 0 | D14: =COUNTIFS('BOM by Location'!$B$5:$B$170,A14,'BOM by Location'!$I$5:$I$170,"",'BOM by Location'!$E$5:$E$170,"<>") -> 1 | E14: =IF($C$17=0,0,C14/$C$17) -> 0
A15: L | B15: Engineering and services | C15: ='BOM by Location'!J152 -> 37567 | D15: =COUNTIFS('BOM by Location'!$B$5:$B$170,A15,'BOM by Location'!$I$5:$I$170,"",'BOM by Location'!$E$5:$E$170,"<>") -> 1 | E15: =IF($C$17=0,0,C15/$C$17) -> 0.35901464
A16: S | B16: Commissioning and operational spares | C16: ='BOM by Location'!J170 -> 6327.8239 | D16: =COUNTIFS('BOM by Location'!$B$5:$B$170,A16,'BOM by Location'!$I$5:$I$170,"",'BOM by Location'!$E$5:$E$170,"<>") -> 2 | E16: =IF($C$17=0,0,C16/$C$17) -> 0.060472793
B17: Total | C17: =SUM(C4:C16) -> 104639.19 | D17: =SUM(D4:D16) -> 53

Sheet Changes vs Offer
A1: Changes against the Schneider Electric offer (Villa Somalia, version 1)
A3: Reference | B3: Description | C3: Offer qty | D3: Project qty | E3: Delta | F3: Change | G3: Reason
A4: BMENOC0311 | B4: M580 I/O scanner module, FactoryCast, EtherNet/IP & Modbus TCP, 3 ports | C4: 2 | D4: =SUMIF('BOM by Location'!$E$5:$E$170,A4,'BOM by Location'!$G$5:$G$170) -> 3 | E4: =D4-C4 -> 1 | F4: Quantity | G4: Second NOC0311 for the second SCADA LAN path (sheet 001).
A5: BMXDDI3202K | B5: X80 digital input module 32 ch 24 V DC sink | C5: 5 | D5: =SUMIF('BOM by Location'!$E$5:$E$170,A5,'BOM by Location'!$G$5:$G$170) -> 7 | E5: =D5-C5 -> 2 | F5: Quantity | G5: 138 hard-wired DI on the X80 racks + 20 % spare needs 6 modules; offer had 4 in use.
A6: BMXFCW303 | B6: 3 m pre-equipped cable, 1 connector + free wires (one per 32-ch module) | C6: 7 | D6: =SUMIF('BOM by Location'!$E$5:$E$170,A6,'BOM by Location'!$G$5:$G$170) -> 9 | E6: =D6-C6 -> 2 | F6: Quantity | G6: One cable per 32-channel module (9 modules).
A7: MCSESM083F23F1 | B7: Modicon Extended Managed Switch 8TX – SCADA LAN (SW1) | C7: 2 | D7: =SUMIF('BOM by Location'!$E$5:$E$170,A7,'BOM by Location'!$G$5:$G$170) -> 1 | E7: =D7-C7 -> -1 | F7: Replaced | G7: SW2 must close the fibre ring; copper-only switch replaced by an FX variant.
A8: NTSNEC1200K | B8: Edge I/O NTS network interface module + base + termination, EtherNet/IP | C8: 7 | D8: =SUMIF('BOM by Location'!$E$5:$E$170,A8,'BOM by Location'!$G$5:$G$170) -> 8 | E8: =D8-C8 -> 1 | F8: Quantity | G8: 7 islands as drawn (President station has 2) + 1 spare.
A9: NTSPFB1002HK | B9: Edge I/O NTS power supply module + base, 24 V DC, bus and field | C9: 7 | D9: =SUMIF('BOM by Location'!$E$5:$E$170,A9,'BOM by Location'!$G$5:$G$170) -> 8 | E9: =D9-C9 -> 1 | F9: Quantity | G9: One per island (7) + 1 spare.
A10: NTSXTB02030H | B10: Screw terminal block 2 pt, 5 mm, for power supply module | C10: 12 | D10: =SUMIF('BOM by Location'!$E$5:$E$170,A10,'BOM by Location'!$G$5:$G$170) -> 14 | E10: =D10-C10 -> 2 | F10: Quantity | G10: Two terminal blocks per power supply module (7 modules).
A11: NTSDDI1602XK | B11: Edge I/O NTS discrete input 16 ch 24 V DC sink + base | C11: 19 | D11: =SUMIF('BOM by Location'!$E$5:$E$170,A11,'BOM by Location'!$G$5:$G$170) -> 20 | E11: =D11-C11 -> 1 | F11: Quantity | G11: Location quantities add to 19 installed; spare was not on top.
A12: NTSXTB18001XH | B12: Screw terminal block 18 pt, 5 mm, high-height (DI) | C12: 18 | D12: =SUMIF('BOM by Location'!$E$5:$E$170,A12,'BOM by Location'!$G$5:$G$170) -> 19 | E12: =D12-C12 -> 1 | F12: Quantity | G12: One terminal block per DI module (offer short by 1 at LVDB 1).
A13: NTSDDO1602K | B13: Edge I/O NTS discrete output 16 ch 24 V DC 0.5 A + base | C13: 7 | D13: =SUMIF('BOM by Location'!$E$5:$E$170,A13,'BOM by Location'!$G$5:$G$170) -> 8 | E13: =D13-C13 -> 1 | F13: Quantity | G13: 7 installed + 1 spare.
A14: NTSXTB18001H | B14: Screw terminal block 18 pt, 3.81 mm, low-height (DO) | C14: 6 | D14: =SUMIF('BOM by Location'!$E$5:$E$170,A14,'BOM by Location'!$G$5:$G$170) -> 7 | E14: =D14-C14 -> 1 | F14: Quantity | G14: One terminal block per DO module (offer short by 1 at LVDB 1).
A15: PAS600 | B15: EcoStruxure Universal Panel Server 110–277 V AC/DC | C15: 7 | D15: =SUMIF('BOM by Location'!$E$5:$E$170,A15,'BOM by Location'!$G$5:$G$170) -> 8 | E15: =D15-C15 -> 1 | F15: Quantity | G15: 7 installed + 1 spare (offer spare not on top).
... A49: TBC-SVC-FO | B49: Fibre installation, splicing and OTDR testing | C49: 0 | D49: =SUMIF('BOM by Location'!$E$5:$E$170,A49,'BOM by Location'!$G$5:$G$170) -> 1 | E49: =D49-C49 -> 1 | F49: Added | G49: Required by drawings 001/002 or panel design; not in offer.
A51: Options not applied (decision needed)
A52: O1 | B52: PV areas: 4 hard-wired DI per area need 1 × NTSDDI1602XK and no DO module. Reducing from 3 DI + 1 DO per area to 1 DI saves 8 × NTSDDI1602XK, 8 × NTSXTB18001XH, 4 × NTSDDO1602K and 4 × NTSXTB18001H. Not applied because drawing 003 and the offer show 3 DI + 1 DO; keep if combiner-box signals are expected.
A53: O2 | B53: Hot-standby controller: replace BMEP582040 + spare by an M580 hot-standby pair (BMEH58xxxx + sync link) if the client requires controller redundancy.
A54: O3 | B54: Relays P5M30 and PM5320 meters: remove from this BOM if the GIS panel / LV board vendors already supply them.

Sheet IO Capacity
A1: Hard-wired I/O capacity check
A3: Spare required | B3: 0.2 | C3: Input. Required DI/DO counts come from docs/villa-somalia-io-list.csv (types DI and DO).
A5: Area | B5: Locations | C5: Type | D5: Required (I/O list) | E5: Required incl. spare | F5: Module | G5: Channels / module | H5: Modules installed | I5: Channels installed | J5: Free channels | K5: Free % | L5: Check
A6: X80 racks (main + Rack 2) | B6: B, C | C6: DI | D6: 138 | E6: =ROUNDUP(D6*(1+$B$3),0) -> 166 | F6: BMXDDI3202K | G6: 32 | H6: =SUMIFS('BOM by Location'!$G$5:$G$170,'BOM by Location'!$E$5:$E$170,F6,'BOM by Location'!$B$5:$B$170,"B")+SUMIFS('BOM by Location'!$G$5:$G$170,'BOM by Location'!$E$5:$E$170,F6,'BOM by Location'!$B$5:$B$170,"C") -> 6 | I6: =G6*H6 -> 192 | J6: =I6-D6 -> 54 | K6: =IF(I6=0,0,J6/I6) -> 0.28125 | L6: =IF(I6>=E6,"OK","SHORT") -> OK
A7: X80 racks (main + Rack 2) | B7: B, C | C7: DO | D7: 26 | E7: =ROUNDUP(D7*(1+$B$3),0) -> 32 | F7: BMXDDO3202K | G7: 32 | H7: =SUMIFS('BOM by Location'!$G$5:$G$170,'BOM by Location'!$E$5:$E$170,F7,'BOM by Location'!$B$5:$B$170,"B")+SUMIFS('BOM by Location'!$G$5:$G$170,'BOM by Location'!$E$5:$E$170,F7,'BOM by Location'!$B$5:$B$170,"C") -> 3 | I7: =G7*H7 -> 96 | J7: =I7-D7 -> 70 | K7: =IF(I7=0,0,J7/I7) -> 0.72916667 | L7: =IF(I7>=E7,"OK","SHORT") -> OK
A8: President TX station | B8: E1 | C8: DI | D8: 29 | E8: =ROUNDUP(D8*(1+$B$3),0) -> 35 | F8: NTSDDI1602XK | G8: 16 | H8: =SUMIFS('BOM by Location'!$G$5:$G$170,'BOM by Location'!$E$5:$E$170,F8,'BOM by Location'!$B$5:$B$170,"E1") -> 4 | I8: =G8*H8 -> 64 | J8: =I8-D8 -> 35 | K8: =IF(I8=0,0,J8/I8) -> 0.546875 | L8: =IF(I8>=E8,"OK","SHORT") -> OK
A9: President TX station | B9: E1 | C9: DO | D9: 11 | E9: =ROUNDUP(D9*(1+$B$3),0) -> 14 | F9: NTSDDO1602K | G9: 16 | H9: =SUMIFS('BOM by Location'!$G$5:$G$170,'BOM by Location'!$E$5:$E$170,F9,'BOM by Location'!$B$5:$B$170,"E1") -> 2 | I9: =G9*H9 -> 32 | J9: =I9-D9 -> 21 | K9: =IF(I9=0,0,J9/I9) -> 0.65625 | L9: =IF(I9>=E9,"OK","SHORT") -> OK
A10: Prime Minister TX station | B10: E2 | C10: DI | D10: 29 | E10: =ROUNDUP(D10*(1+$B$3),0) -> 35 | F10: NTSDDI1602XK | G10: 16 | H10: =SUMIFS('BOM by Location'!$G$5:$G$170,'BOM by Location'!$E$5:$E$170,F10,'BOM by Location'!$B$5:$B$170,"E2") -> 3 | I10: =G10*H10 -> 48 | J10: =I10-D10 -> 19 | K10: =IF(I10=0,0,J10/I10) -> 0.39583333 | L10: =IF(I10>=E10,"OK","SHORT") -> OK
A11: Prime Minister TX station | B11: E2 | C11: DO | D11: 11 | E11: =ROUNDUP(D11*(1+$B$3),0) -> 14 | F11: NTSDDO1602K | G11: 16 | H11: =SUMIFS('BOM by Location'!$G$5:$G$170,'BOM by Location'!$E$5:$E$170,F11,'BOM by Location'!$B$5:$B$170,"E2") -> 1 | I11: =G11*H11 -> 16 | J11: =I11-D11 -> 5 | K11: =IF(I11=0,0,J11/I11) -> 0.3125 | L11: =IF(I11>=E11,"OK","SHORT") -> OK
A12: PV areas 1–4 (total) | B12: F | C12: DI | D12: 16 | E12: =ROUNDUP(D12*(1+$B$3),0) -> 20 | F12: NTSDDI1602XK | G12: 16 | H12: =SUMIFS('BOM by Location'!$G$5:$G$170,'BOM by Location'!$E$5:$E$170,F12,'BOM by Location'!$B$5:$B$170,"F") -> 12 | I12: =G12*H12 -> 192 | J12: =I12-D12 -> 176 | K12: =IF(I12=0,0,J12/I12) -> 0.91666667 | L12: =IF(I12>=E12,"OK","SHORT") -> OK
A13: PV areas 1–4 (total) | B13: F | C13: DO | D13: 0 | E13: =ROUNDUP(D13*(1+$B$3),0) -> 0 | F13: NTSDDO1602K | G13: 16 | H13: =SUMIFS('BOM by Location'!$G$5:$G$170,'BOM by Location'!$E$5:$E$170,F13,'BOM by Location'!$B$5:$B$170,"F") -> 4 | I13: =G13*H13 -> 64 | J13: =I13-D13 -> 64 | K13: =IF(I13=0,0,J13/I13) -> 1 | L13: =IF(I13>=E13,"OK","SHORT") -> OK
